Workbook

Sheet Histórico de Pagamentos
A1: Etapa | B1: Data | C1: Pagador | D1: Descricao | E1: Valor | F1: Pedido | G1: NF | H1: PIX
A2: Outros | B2: 44335 | C2: Ricardo | D2: 50% custo anual para domínio do Site ForteGB | E2: 67
A3: Documentação | B3: 44336 | C3: Ricardo | D3: CND's Juciléia/Hercílio e do terreno P-31 | E3: 88.83
A4: Documentação | B4: 44336 | C4: Ricardo | D4: CND complementar | E4: 59.07
A5: Documentação | B5: 44336 | C5: Ricardo | D5: Reconhecimento firma | E5: 21.04
A6: Documentação | B6: 44336 | C6: Felipe | D6: Reconhecimento firma | E6: 21.04
A7: Terreno | B7: 44349 | C7: Ricardo | D7: 50% aquisição do terreno P-31 | E7: 90000
A8: Terreno | B8: 44349 | C8: Felipe | D8: 50% aquisição do terreno P-31 | E8: 90000
A9: Documentação | B9: 44349 | C9: Ricardo | D9: 50% do ITBI do Terreno | E9: 1500
A10: Documentação | B10: 44349 | C10: Ricardo | D10: 50% taxa de Escritura do terreno | E10: 1309.43
A11: Documentação | B11: 44349 | C11: Felipe | D11: 50% do ITBI do Terreno | E11: 1500
A12: Documentação | B12: 44349 | C12: Felipe | D12: 50% taxa de Escritura do terreno | E12: 1309.43
A13: Terreno | B13: 44350 | C13: Ricardo | D13: 50% da bonificação do olheiro Adriano | E13: 500
... A29: Projeto | B29: 44480 | C29: Ricardo | D29: Cópias do projeto estrutural para o Sr. José (Pedreiro) | E29: 49.5
A30: Elétrica | B30: 44480 | C30: Adilson | D30: Conduscam - Cabos 255 Poste 18m preto e 6m azul | E30: 110.4 | F30: Não | G30: Sim | H30: Sim
A31: Fundação | B31: 44480 | C31: Ricardo | D31: Maruí - Madeiras para gabarito, baldrame e complemento do barraco | E31: 2200 | F31: Sim
A32: Fundação | B32: 44480 | C32: Felipe | D32: Maruí - Madeiras para gabarito, baldrame e complemento do barraco | E32: 2200 | F32: Sim
A33: Fundação | B33: 44483 | C33: Adilson | D33: Mercado Livre - Protetor plástico para ponta de vergalhão | E33: 82.8 | G33: Sim
A34: Preliminares | B34: 44483 | C34: Ricardo | D34: Terraplanagem e limpeza do terreno | E34: 1800
A35: Preliminares | B35: 44484 | C35: Adilson | D35: S SIlva - Cadeado e corrente par o abrigo provisório (barraco) | E35: 75 | F35: Sim
A36: Projeto | B36: 44485 | C36: Ricardo | D36: Cyberdocs - Impressão de Projeto | E36: 7.3 | F36: Sim | G36: Não | H36: Sim
A37: Fundação | B37: 44487 | C37: Adilson | D37: Espaçadores tipo roseta S30 (pacote com 300 pçs) | E37: 79
A38: Fundação | B38: 44487 | C38: Ricardo | D38: Ferro Pronto - Ferragens para estacas da casa | E38: 1716 | F38: Sim | G38: Não | H38: Sim
A39: Projeto | B39: 44468 | C39: Adilson | D39: Penúltima parcela do contrato com a N&ED (parcela 3 de 4) | E39: 748.67
A40: Projeto | B40: 44489 | C40: Adilson | D40: N&ED - Projetos Arquitetonico e Complementares Parcela 4 de 4 | E40: 748.67 | F40: Não | G40: Não | H40: Sim
A41: Fundação | B41: 44489 | C41: Adilson | D41: Ferro Pronto - Ferragens para estacas do muro | E41: 468 | F41: Sim | G41: Não | H41: Sim
A42: Fundação | B42: 44490 | C42: Ricardo | D42: Anderson Perfurações - Perfuração mecanizada de brocas (casa e muros) | E42: 1400 | F42: Não | G42: Não | H42: Sim
A43: Documentação | B43: 44490 | C43: Ricardo | D43: PMH - Taxa de alvará de construção | E43: 258.74 | F43: Sim | G43: Não | H43: Sim
A44: Projeto | B44: 44491 | C44: Adilson | D44: Cyberdoc - Impressão projeto hidráulico | E44: 29 | F44: Sim
A45: Projeto | B45: 44491 | C45: Ricardo | D45: Cyberdoc - Impressão projeto estrutural | E45: 43.8 | F45: Sim | H45: Sim
A46: Outros | B46: 44492 | C46: Adilson | D46: Guindola - Alimentação Equipe Concretagem Brocas | E46: 72 | H46: Sim
A47: Outros | B47: 44492 | C47: Adilson | D47: Guindola - Almoço Ricardo e Adilson | E47: 69
A48: Fundação | B48: 44494 | C48: Felipe | D48: Rodrigues - Areia grossa e pedrisco | E48: 1030 | H48: Sim
A49: Paredes e muros | B49: 44494 | C49: Adilson | D49: 63 sacos de cimento | E49: 1812.6
A50: Fundação | B50: 44495 | C50: Ricardo | D50: Ferro Pronto - Ferragem armada para baldrames (casa e muros) | E50: 11200 | F50: Sim | G50: Não | H50: Sim
A51: Fundação | B51: 44497 | C51: Felipe | D51: Campmix - Concreto usinado para estacas 7m3 | E51: 2310 | G51: Sim
A52: Fundação | B52: 44499 | C52: Ricardo | D52: José Salla - Mão-de-Obra | E52: 2000 | F52: Não | G52: Não | H52: Sim
A53: Fundação | B53: 44501 | C53: Adilson | D53: Arame recozido (10 kgs) | E53: 235
A54: Fundação | B54: 44501 | C54: Adilson | D54: Aluguel de martelete elétrico de 11 kgs | E54: 100
A55: Paredes e muros | B55: 44504 | C55: Ricardo | D55: 103 barras de ferro 8mm CA50 nervurado (barras de 12m) | E55: 3811
...

Sheet Rateio e Estimativa somente lei
C2: Planilha de rateio de valor investido em construção residencial (CASA 02 : Ricardo, Adilson e Felipe) | K2: ESTIMATIVA x REAL (CASA 02 / Terreno P-31)
C3: Ricardo | D3: porcentagem | E3: Adilson | F3: porcentagem | G3: Felipe | H3: porcentagem | I3: Total | K3: CUSTO ESTIMADO P-31 | L3: CUSTO REAL P-31 | M3: DESVIO (em R$) | N3: DESVIO (em %)
B4: Terreno | C4: =SUMIFS('Histórico de Pagamentos'!E:E,'Histórico de Pagamentos'!A:A,B4,'Histórico de Pagamentos'!C:C,C$3) -> 90500 | D4: 0.5 | E4: =SUMIFS('Histórico de Pagamentos'!E:E,'Histórico de Pagamentos'!A:A,B4,'Histórico de Pagamentos'!C:C,E$3) -> 0 | F4: 0 | G4: =SUMIFS('Histórico de Pagamentos'!E:E,'Histórico de Pagamentos'!A:A,B4,'Histórico de Pagamentos'!C:C,G$3) -> 90500 | H4: 0.5 | I4: =C4+E4+G4 -> 181000 | K4: 180000 | L4: =I4 -> 181000 | M4: =IF(L4=0,"",L4-K4) -> 1000 | N4: =IF(L4=0,"",(L4-K4)/K4) -> 0.0055555556
B5: Documentação | C5: =SUMIFS('Histórico de Pagamentos'!E:E,'Histórico de Pagamentos'!A:A,B5,'Histórico de Pagamentos'!C:C,C$3) -> 4275.92 | D5: 0.51035161 | E5: =SUMIFS('Histórico de Pagamentos'!E:E,'Histórico de Pagamentos'!A:A,B5,'Histórico de Pagamentos'!C:C,E$3) -> 236.23 | F5: 0.028699723 | G5: =SUMIFS('Histórico de Pagamentos'!E:E,'Histórico de Pagamentos'!A:A,B5,'Histórico de Pagamentos'!C:C,G$3) -> 7871.36 | H5: 0.46094867 | I5: =C5+E5+G5 -> 12383.51 | K5: 16000 | L5: =I5 -> 12383.51 | M5: =IF(L5=0,"",L5-K5) -> -3616.49 | N5: =IF(L5=0,"",(L5-K5)/K5) -> -0.22603063
B6: Projeto | C6: =SUMIFS('Histórico de Pagamentos'!E:E,'Histórico de Pagamentos'!A:A,B6,'Histórico de Pagamentos'!C:C,C$3) -> 3615.04 | D6: 0.49493705 | E6: =SUMIFS('Histórico de Pagamentos'!E:E,'Histórico de Pagamentos'!A:A,B6,'Histórico de Pagamentos'!C:C,E$3) -> 2849 | F6: 0.3900581 | G6: =SUMIFS('Histórico de Pagamentos'!E:E,'Histórico de Pagamentos'!A:A,B6,'Histórico de Pagamentos'!C:C,G$3) -> 840 | H6: 0.11500485 | I6: =C6+E6+G6 -> 7304.04 | K6: 7000 | L6: =I6 -> 7304.04 | M6: =IF(L6=0,"",L6-K6) -> 304.04 | N6: =IF(L6=0,"",(L6-K6)/K6) -> 0.043434286
B7: Preliminares | C7: =SUMIFS('Histórico de Pagamentos'!E:E,'Histórico de Pagamentos'!A:A,B7,'Histórico de Pagamentos'!C:C,C$3) -> 1800 | D7: 0.96 | E7: =SUMIFS('Histórico de Pagamentos'!E:E,'Histórico de Pagamentos'!A:A,B7,'Histórico de Pagamentos'!C:C,E$3) -> 75 | F7: 0.04 | G7: =SUMIFS('Histórico de Pagamentos'!E:E,'Histórico de Pagamentos'!A:A,B7,'Histórico de Pagamentos'!C:C,G$3) -> 0 | H7: 0 | I7: =C7+E7+G7 -> 1875 | K7: 2000 | L7: =I7 -> 1875 | M7: =IF(L7=0,"",L7-K7) -> -125 | N7: =IF(L7=0,"",(L7-K7)/K7) -> -0.0625
B8: Fundação | C8: =SUMIFS('Histórico de Pagamentos'!E:E,'Histórico de Pagamentos'!A:A,B8,'Histórico de Pagamentos'!C:C,C$3) -> 29372 | D8: 0.80013512 | E8: =SUMIFS('Histórico de Pagamentos'!E:E,'Histórico de Pagamentos'!A:A,B8,'Histórico de Pagamentos'!C:C,E$3) -> 1796.8 | F8: 0.048947391 | G8: =SUMIFS('Histórico de Pagamentos'!E:E,'Histórico de Pagamentos'!A:A,B8,'Histórico de Pagamentos'!C:C,G$3) -> 5540 | H8: 0.15091749 | I8: =C8+E8+G8 -> 36708.8 | K8: 38000 | L8: =I8 -> 36708.8 | M8: =IF(L8=0,"",L8-K8) -> -1291.2 | N8: =IF(L8=0,"",(L8-K8)/K8) -> -0.033978947
B9: Paredes e muros | C9: =SUMIFS('Histórico de Pagamentos'!E:E,'Histórico de Pagamentos'!A:A,B9,'Histórico de Pagamentos'!C:C,C$3) -> 56389.12 | D9: 0.68682857 | E9: =SUMIFS('Histórico de Pagamentos'!E:E,'Histórico de Pagamentos'!A:A,B9,'Histórico de Pagamentos'!C:C,E$3) -> 11974.85 | F9: 0.1458556 | G9: =SUMIFS('Histórico de Pagamentos'!E:E,'Histórico de Pagamentos'!A:A,B9,'Histórico de Pagamentos'!C:C,G$3) -> 13736.75 | H9: 0.16731583 | I9: =C9+E9+G9 -> 82100.72 | K9: 70000 | L9: =I9 -> 82100.72 | M9: =IF(L9=0,"",L9-K9) -> 12100.72 | N9: =IF(L9=0,"",(L9-K9)/K9) -> 0.17286743
B10: Laje | C10: =SUMIFS('Histórico de Pagamentos'!E:E,'Histórico de Pagamentos'!A:A,B10,'Histórico de Pagamentos'!C:C,C$3) -> 28642 | D10: 0.86607549 | E10: =SUMIFS('Histórico de Pagamentos'!E:E,'Histórico de Pagamentos'!A:A,B10,'Histórico de Pagamentos'!C:C,E$3) -> 4069.02 | F10: 0.12303884 | G10: =SUMIFS('Histórico de Pagamentos'!E:E,'Histórico de Pagamentos'!A:A,B10,'Histórico de Pagamentos'!C:C,G$3) -> 360 | H10: 0.010885664 | I10: =C10+E10+G10 -> 33071.02 | K10: 32000 | L10: =I10 -> 33071.02 | M10: =IF(L10=0,"",L10-K10) -> 1071.02 | N10: =IF(L10=0,"",(L10-K10)/K10) -> 0.033469375
B11: Telhado | C11: =SUMIFS('Histórico de Pagamentos'!E:E,'Histórico de Pagamentos'!A:A,B11,'Histórico de Pagamentos'!C:C,C$3) -> 29800 | D11: 0.97971529 | E11: =SUMIFS('Histórico de Pagamentos'!E:E,'Histórico de Pagamentos'!A:A,B11,'Histórico de Pagamentos'!C:C,E$3) -> 50 | F11: 0.0016438176 | G11: =SUMIFS('Histórico de Pagamentos'!E:E,'Histórico de Pagamentos'!A:A,B11,'Histórico de Pagamentos'!C:C,G$3) -> 567 | H11: 0.018640892 | I11: =C11+E11+G11 -> 30417 | K11: 25000 | L11: =I11 -> 30417 | M11: =IF(L11=0,"",L11-K11) -> 5417 | N11: =IF(L11=0,"",(L11-K11)/K11) -> 0.21668
B12: Reboco | C12: =SUMIFS('Histórico de Pagamentos'!E:E,'Histórico de Pagamentos'!A:A,B12,'Histórico de Pagamentos'!C:C,C$3) -> 25471.38 | D12: 0.75591971 | E12: =SUMIFS('Histórico de Pagamentos'!E:E,'Histórico de Pagamentos'!A:A,B12,'Histórico de Pagamentos'!C:C,E$3) -> 1714.5 | F12: 0.050881591 | G12: =SUMIFS('Histórico de Pagamentos'!E:E,'Histórico de Pagamentos'!A:A,B12,'Histórico de Pagamentos'!C:C,G$3) -> 6510 | H12: 0.19319869 | I12: =C12+E12+G12 -> 33695.88 | K12: 15000 | L12: =I12 -> 33695.88 | M12: =IF(L12=0,"",L12-K12) -> 18695.88 | N12: =IF(L12=0,"",(L12-K12)/K12) -> 1.246392
B13: Churrasqueira | C13: =SUMIFS('Histórico de Pagamentos'!E:E,'Histórico de Pagamentos'!A:A,B13,'Histórico de Pagamentos'!C:C,C$3) -> 0 | D13: 0 | E13: =SUMIFS('Histórico de Pagamentos'!E:E,'Histórico de Pagamentos'!A:A,B13,'Histórico de Pagamentos'!C:C,E$3) -> 0 | F13: 0 | G13: =SUMIFS('Histórico de Pagamentos'!E:E,'Histórico de Pagamentos'!A:A,B13,'Histórico de Pagamentos'!C:C,G$3) -> 3150 | H13: 1 | I13: =C13+E13+G13 -> 3150 | K13: 3500 | L13: =I13 -> 3150 | M13: =IF(L13=0,"",L13-K13) -> -350 | N13: =IF(L13=0,"",(L13-K13)/K13) -> -0.1
B14: Bancadas/soleiras | C14: =SUMIFS('Histórico de Pagamentos'!E:E,'Histórico de Pagamentos'!A:A,B14,'Histórico de Pagamentos'!C:C,C$3) -> 19875 | D14: 1 | E14: =SUMIFS('Histórico de Pagamentos'!E:E,'Histórico de Pagamentos'!A:A,B14,'Histórico de Pagamentos'!C:C,E$3) -> 0 | F14: 0 | G14: =SUMIFS('Histórico de Pagamentos'!E:E,'Histórico de Pagamentos'!A:A,B14,'Histórico de Pagamentos'!C:C,G$3) -> 0 | H14: 0 | I14: =C14+E14+G14 -> 19875 | K14: 25000 | L14: =I14 -> 19875 | M14: =IF(L14=0,"",L14-K14) -> -5125 | N14: =IF(L14=0,"",(L14-K14)/K14) -> -0.205
B15: Hidráulica | C15: =SUMIFS('Histórico de Pagamentos'!E:E,'Histórico de Pagamentos'!A:A,B15,'Histórico de Pagamentos'!C:C,C$3) -> 22616.15 | D15: 0.9477671 | E15: =SUMIFS('Histórico de Pagamentos'!E:E,'Histórico de Pagamentos'!A:A,B15,'Histórico de Pagamentos'!C:C,E$3) -> 862.5 | F15: 0.036578554 | G15: =SUMIFS('Histórico de Pagamentos'!E:E,'Histórico de Pagamentos'!A:A,B15,'Histórico de Pagamentos'!C:C,G$3) -> 369.12 | H15: 0.015654349 | I15: =C15+E15+G15 -> 23847.77 | K15: 18000 | L15: =I15 -> 23847.77 | M15: =IF(L15=0,"",L15-K15) -> 5847.77 | N15: =IF(L15=0,"",(L15-K15)/K15) -> 0.32487611
... B21: Louças e metais | C21: =SUMIFS('Histórico de Pagamentos'!E:E,'Histórico de Pagamentos'!A:A,B21,'Histórico de Pagamentos'!C:C,C$3) -> 5761.48 | D21: 0.56423862 | E21: =SUMIFS('Histórico de Pagamentos'!E:E,'Histórico de Pagamentos'!A:A,B21,'Histórico de Pagamentos'!C:C,E$3) -> 3102.59 | F21: 0.30384573 | G21: =SUMIFS('Histórico de Pagamentos'!E:E,'Histórico de Pagamentos'!A:A,B21,'Histórico de Pagamentos'!C:C,G$3) -> 1347 | H21: 0.13191566 | I21: =C21+E21+G21 -> 10211.07 | K21: 20000 | L21: =I21 -> 10211.07 | M21: =IF(L21=0,"",L21-K21) -> -9788.93 | N21: =IF(L21=0,"",(L21-K21)/K21) -> -0.4894465
B22: Armários | C22: =SUMIFS('Histórico de Pagamentos'!E:E,'Histórico de Pagamentos'!A:A,B22,'Histórico de Pagamentos'!C:C,C$3) -> 0 | E22: =SUMIFS('Histórico de Pagamentos'!E:E,'Histórico de Pagamentos'!A:A,B22,'Histórico de Pagamentos'!C:C,E$3) -> 0 | G22: =SUMIFS('Histórico de Pagamentos'!E:E,'Histórico de Pagamentos'!A:A,B22,'Histórico de Pagamentos'!C:C,G$3) -> 0 | I22: =C22+E22+G22 -> 0 | K22: 33000 | L22: =I22 -> 0 | M22: =IF(L22=0,"",L22-K22) | N22: =IF(L22=0,"",(L22-K22)/K22)
B23: Jardinagem | C23: =SUMIFS('Histórico de Pagamentos'!E:E,'Histórico de Pagamentos'!A:A,B23,'Histórico de Pagamentos'!C:C,C$3) -> 510 | E23: =SUMIFS('Histórico de Pagamentos'!E:E,'Histórico de Pagamentos'!A:A,B23,'Histórico de Pagamentos'!C:C,E$3) -> 1065 | G23: =SUMIFS('Histórico de Pagamentos'!E:E,'Histórico de Pagamentos'!A:A,B23,'Histórico de Pagamentos'!C:C,G$3) -> 3536.9 | I23: =C23+E23+G23 -> 5111.9 | K23: 1600 | L23: =I23 -> 5111.9 | M23: =IF(L23=0,"",L23-K23) -> 3511.9 | N23: =IF(L23=0,"",(L23-K23)/K23) -> 2.1949375
B24: Limpeza pós-obra | C24: =SUMIFS('Histórico de Pagamentos'!E:E,'Histórico de Pagamentos'!A:A,B24,'Histórico de Pagamentos'!C:C,C$3) -> 1810.28 | D24: 0.19151921 | E24: =SUMIFS('Histórico de Pagamentos'!E:E,'Histórico de Pagamentos'!A:A,B24,'Histórico de Pagamentos'!C:C,E$3) -> 1564.66 | F24: 0.40386275 | G24: =SUMIFS('Histórico de Pagamentos'!E:E,'Histórico de Pagamentos'!A:A,B24,'Histórico de Pagamentos'!C:C,G$3) -> 300 | H24: 0.40461804 | I24: =C24+E24+G24 -> 3674.94 | K24: 400 | L24: =I24 -> 3674.94 | M24: =IF(L24=0,"",L24-K24) -> 3274.94 | N24: =IF(L24=0,"",(L24-K24)/K24) -> 8.18735
B25: IPTU/cond./água/luz | C25: =SUMIFS('Histórico de Pagamentos'!E:E,'Histórico de Pagamentos'!A:A,B25,'Histórico de Pagamentos'!C:C,C$3) -> 6474.76 | D25: 0.34253005 | E25: =SUMIFS('Histórico de Pagamentos'!E:E,'Histórico de Pagamentos'!A:A,B25,'Histórico de Pagamentos'!C:C,E$3) -> 12092.73 | F25: 0.49956129 | G25: =SUMIFS('Histórico de Pagamentos'!E:E,'Histórico de Pagamentos'!A:A,B25,'Histórico de Pagamentos'!C:C,G$3) -> 4336.19 | H25: 0.15790866 | I25: =C25+E25+G25 -> 22903.68 | K25: 6000 | L25: =I25 -> 22903.68 | M25: =IF(L25=0,"",L25-K25) -> 16903.68 | N25: =IF(L25=0,"",(L25-K25)/K25) -> 2.81728
B26: Outros | C26: =SUMIFS('Histórico de Pagamentos'!E:E,'Histórico de Pagamentos'!A:A,B26,'Histórico de Pagamentos'!C:C,C$3) -> 2458.59 | D26: 0.77438101 | E26: =SUMIFS('Histórico de Pagamentos'!E:E,'Histórico de Pagamentos'!A:A,B26,'Histórico de Pagamentos'!C:C,E$3) -> 2616.32 | F26: 0.22561899 | G26: =SUMIFS('Histórico de Pagamentos'!E:E,'Histórico de Pagamentos'!A:A,B26,'Histórico de Pagamentos'!C:C,G$3) -> 0 | H26: 0 | I26: =C26+E26+G26 -> 5074.91 | K26: 4500 | L26: =I26 -> 5074.91 | M26: =IF(L26=0,"",L26-K26) -> 574.91 | N26: =IF(L26=0,"",(L26-K26)/K26) -> 0.12775778
C27: RICARDO | E27: ADILSON | G27: FELIPE | K27: =SUM(K4:K26) -> 638000 | L27: =SUM(L4:L26) -> 662860.71 | M27: =L27-K27 -> 24860.71 | N27: =IF(L27=0,"",(L27-K27)/K27) -> 0.03896663
B28: TOTAL | C28: =SUM(C4:C26) -> 429877.8 | D28: =C28/I28 -> 0.64851905 | E28: =SUM(E4:E26) -> 60894.77 | F28: =E28/I28 -> 0.091866616 | G28: =SUM(G4:G26) -> 172088.14 | H28: =G28/I28 -> 0.25961433 | I28: =SUM(I4:I26) -> 662860.71
B31: Histórico de realização de Venda:
B32: Data: 09/04/22 | C32: Ricardo | E32: Adilson | G32: Felipe | I32: Valor da venda:
B33: Venda de tábuas | C33: =I33*D33 -> 276.6 | D33: 0.6915 | E33: =I33*F33 -> 26.92 | F33: 0.0673 | G33: =I33*H33 -> 96.48 | H33: 0.2412 | I33: 400
B35: Data: 19/04/22 | C35: Ricardo | E35: Adilson | G35: Felipe | I35: Valor da venda:
B36: Venda madeirites | C36: =I36*D36 -> 275.4 | D36: 0.6885 | E36: =I36*F36 -> 27.2 | F36: 0.068 | G36: =I36*H36 -> 97.36 | H36: 0.2434 | I36: 400
B38: Data: 02/05/22 | C38: Ricardo | E38: Adilson | G38: Felipe | I38: Valor da venda:
B39: Venda tubos PVC | C39: =I39*D39 -> 88.582 | D39: 0.6814 | E39: =I39*F39 -> 9.451 | F39: 0.0727 | G39: =I39*H39 -> 31.967 | H39: 0.2459 | I39: 130

Sheet Cenário Venda
B2: CENARIO COM TERRENO BANDEIRAS
B3: P-31 | C3: 870K Terreno 180K | D3: 880K Terreno 180K | E3: 890K Terreno 180K
B4: Custo Total Construção | C4: 660000 | D4: 660000 | E4: 660000
B6: Em Dinheiro | C6: =C13-C12 -> 710522.38 | D6: =D13-D12 -> 720522.38 | E6: =E13-E12 -> 730522.38
B7: Terreno Preço Venda | C7: 180000 | D7: 180000 | E7: 180000
B8: Escritura | C8: -4835.75 | D8: -4835.75 | E8: -4835.75
B9: Registro | C9: -3086.63 | D9: -3086.63 | E9: -3086.63
B10: ITBI | C10: =-(0.02*C7) -> -3600 | D10: =-(0.02*D7) -> -3600 | E10: =-(0.02*E7) -> -3600
B11: Corretagem 5% | C11: =C7*0.05*(-1) -> -9000 | D11: =D7*0.05*(-1) -> -9000 | E11: =E7*0.05*(-1) -> -9000
B12: Terreno Dinheiro Livre na Mão | C12: =C7+(SUM(C8:C11)) -> 159477.62 | D12: =D7+(SUM(D8:D11)) -> 159477.62 | E12: =E7+(SUM(E8:E11)) -> 159477.62
B13: Total em Dinheiro | C13: 870000 | D13: 880000 | E13: 890000
B17: Lucro Declarado | C17: =C13-C4 -> 210000 | D17: =D13-D4 -> 220000 | E17: =E13-E4 -> 230000
B18: Imposto | C18: =C17*0.15 -> 31500 | D18: =D17*0.15 -> 33000 | E18: =E17*0.15 -> 34500
B19: Lucro Líquido | C19: =C17-C18 -> 178500 | D19: =D17-D18 -> 187000 | E19: =E17-E18 -> 195500
B20: Margem Líquida | C20: =C19/C4 -> 0.27045455 | D20: =D19/D4 -> 0.28333333 | E20: =E19/E4 -> 0.29621212
B25: CENARIO COM APTO
B26: P-31 | C26: Oferta Inicial c/ Transf | D26: Oferta Inicial s/ Transf | E26: Contra 1 c/ Transf | F26: Contra 1 s/ Transf | G26: Contra 1 c/ Transf
B27: Custo Total Construção | C27: 660000 | D27: 660000 | E27: 660000 | F27: 660000 | G27: 660000
B29: Em Dinheiro | C29: 700000 | D29: 700000 | E29: 720000 | F29: 720000 | G29: 720000
B30: Apartamento | C30: 180000 | D30: 180000 | E30: 180000 | F30: 180000 | G30: 160000
B31: Escritura | C31: -4835.75 | D31: 0 | E31: -4835.75 | F31: 0 | G31: 0
B32: Registro | C32: -3086.63 | D32: 0 | E32: -3086.63 | F32: 0 | G32: 0
B33: ITBI | C33: =-(0.02*C30) -> -3600 | D33: =-(0.02*D30) -> -3600 | E33: =-(0.02*E30) -> -3600 | F33: =-(0.02*F30) -> -3600 | G33: =-(0.02*G30) -> -3200
B34: Apartamento Livre | C34: =SUM(C30:C33) -> 168477.62 | D34: =SUM(D30:D33) -> 176400 | E34: =SUM(E30:E33) -> 168477.62 | F34: =SUM(F30:F33) -> 176400 | G34: =SUM(G30:G33) -> 156800
B35: Dinheiro na Mão | C35: =C34+C29 -> 868477.62 | D35: =D34+D29 -> 876400 | E35: =E34+E29 -> 888477.62 | F35: =F34+F29 -> 896400 | G35: =G34+G29 -> 876800
B39: Lucro Declarado | C39: =C35-C27 -> 208477.62 | D39: =D35-D27 -> 216400 | E39: =E35-E27 -> 228477.62 | F39: =F35-F27 -> 236400 | G39: =G35-G27 -> 216800
B40: Imposto | C40: =C39*0.15 -> 31271.643 | D40: =D39*0.15 -> 32460 | E40: =E39*0.15 -> 34271.643 | F40: =F39*0.15 -> 35460 | G40: =G39*0.15 -> 32520
B41: Lucro Líquido | C41: =C39-C40 -> 177205.98 | D41: =D39-D40 -> 183940 | E41: =E39-E40 -> 194205.98 | F41: =F39-F40 -> 200940 | G41: =G39-G40 -> 184280
B42: Margem Líquida | C42: =C41/C27 -> 0.2684939 | D42: =D41/D27 -> 0.27869697 | E42: =E41/E27 -> 0.29425148 | F42: =F41/F27 -> 0.30445455 | G42: =G41/G27 -> 0.27921212
B45: CENARIO DINHEIRO
B46: P-31 | C46: 1
B47: Custo Total Construção | C47: 660000 | D47: 660000
B49: Em Dinheiro | C49: 880000 | D49: 800000
B55: Dinheiro na Mão | C55: =C54+C49 -> 880000 | D55: =D54+D49 -> 800000
B59: Lucro Declarado | C59: =C55-C47 -> 220000 | D59: =D55-D47 -> 140000
B60: Imposto | C60: =C59*0.15 -> 33000 | D60: =D59*0.15 -> 21000
B61: Lucro Líquido | C61: =C59-C60 -> 187000 | D61: =D59-D60 -> 119000
B62: Margem Líquida | C62: =C61/C47 -> 0.28333333 | D62: =D61/D47 -> 0.18030303

Sheet Lançamentos perdidos (análise F
A1: Etapa | B1: Data | C1: Pagador | D1: Descricao | E1: Valor
A2: IPTU/cond./água/luz | B2: 45086 | C2: Adilson | D2: MASP - Condomínio P-31 | E2: 301.82
A3: Documentação | B3: 45117 | C3: Felipe | D3: Emissão do Habite-se P-31 | E3: 4077.25
A4: IPTU/cond./água/luz | B4: 45117 | C4: Adilson | D4: MASP - Condomínio P-31 | E4: 301.82
A5: IPTU/cond./água/luz | B5: 45148 | C5: Adilson | D5: MASP - Condomínio P-31 | E5: 301.82
A6: IPTU/cond./água/luz | B6: 45169 | C6: Ricardo | D6: Conta de água (Agosto) | E6: 64.92
A7: IPTU/cond./água/luz | B7: 45169 | C7: Ricardo | D7: Conta de água (Julho) | E7: 64.92
A8: IPTU/cond./água/luz | B8: 45169 | C8: Ricardo | D8: Conta de água (Junho) | E8: 67.06
A9: IPTU/cond./água/luz | B9: 45169 | C9: Ricardo | D9: Conta de água (Maio) | E9: 94.44
A10: IPTU/cond./água/luz | B10: 45169 | C10: Ricardo | D10: Conta de água (Abril) | E10: 61.21
A11: IPTU/cond./água/luz | B11: 45169 | C11: Ricardo | D11: Conta de energia (Abril) | E11: 85.94
A12: IPTU/cond./água/luz | B12: 45169 | C12: Ricardo | D12: Conta de energia (Março) | E12: 86.02
A13: IPTU/cond./água/luz | B13: 45175 | C13: Adilson | D13: MASP - Condomínio P-31 | E13: 301.82
... A33: IPTU/cond./água/luz | B33: 45453 | C33: Adilson | D33: MASP - Condomínio P-31 | E33: 301.82
